Workbook

Sheet Dashboard
B2: DEBT PAYMENT DASHBOARD
B3: Last Updated: | C3: December 28, 2025
B5: KEY METRICS | E5: SELECTED STRATEGY
B7: Total Debt (Original): | C7: =SUM('Debt Inventory'!D4:D28) | E7: Current Strategy: | F7: ='Strategy Selector'!B4
B8: Total Debt (Current): | C8: =SUM('Debt Inventory'!E4:E28)
B9: Total Paid Off: | C9: =C7-C8 | E9: Projected Debt-Free Date: | F9: ='Strategy Selector'!E12
B10: Progress: | C10: =IF(C7>0,C9/C7,0) | E10: Total Interest to Pay: | F10: ='Strategy Selector'!E10
E11: Months to Debt-Free: | F11: ='Strategy Selector'!E11
B12: Monthly Minimum: | C12: =SUM('Debt Inventory'!G4:G28)
B13: Average Interest Rate: | C13: =AVERAGEIF('Debt Inventory'!F4:F28,">0")
B14: Number of Active Debts: | C14: =COUNTIF('Debt Inventory'!E4:E28,">0")
B16: TOP 5 LARGEST DEBTS | E16: PAYMENT BREAKDOWN
B17: Debt Name | C17: Balance | D17: Rate
B18: =IFERROR(INDEX('Debt Inventory'!B4:B28,MATCH(LARGE('Debt Inventory'!E4:E28,1),'Debt Inventory'!E4:E28,0)),"") | C18: =IFERROR(LARGE('Debt Inventory'!E4:E28,1),"") | D18: =IFERROR(INDEX('Debt Inventory'!F4:F28,MATCH(LARGE('Debt Inventory'!E4:E28,1),'Debt Inventory'!E4:E28,0)),"")
B19: =IFERROR(INDEX('Debt Inventory'!B4:B28,MATCH(LARGE('Debt Inventory'!E4:E28,2),'Debt Inventory'!E4:E28,0)),"") | C19: =IFERROR(LARGE('Debt Inventory'!E4:E28,2),"") | D19: =IFERROR(INDEX('Debt Inventory'!F4:F28,MATCH(LARGE('Debt Inventory'!E4:E28,2),'Debt Inventory'!E4:E28,0)),"")
B20: =IFERROR(INDEX('Debt Inventory'!B4:B28,MATCH(LARGE('Debt Inventory'!E4:E28,3),'Debt Inventory'!E4:E28,0)),"") | C20: =IFERROR(LARGE('Debt Inventory'!E4:E28,3),"") | D20: =IFERROR(INDEX('Debt Inventory'!F4:F28,MATCH(LARGE('Debt Inventory'!E4:E28,3),'Debt Inventory'!E4:E28,0)),"")
B21: =IFERROR(INDEX('Debt Inventory'!B4:B28,MATCH(LARGE('Debt Inventory'!E4:E28,4),'Debt Inventory'!E4:E28,0)),"") | C21: =IFERROR(LARGE('Debt Inventory'!E4:E28,4),"") | D21: =IFERROR(INDEX('Debt Inventory'!F4:F28,MATCH(LARGE('Debt Inventory'!E4:E28,4),'Debt Inventory'!E4:E28,0)),"")
B22: =IFERROR(INDEX('Debt Inventory'!B4:B28,MATCH(LARGE('Debt Inventory'!E4:E28,5),'Debt Inventory'!E4:E28,0)),"") | C22: =IFERROR(LARGE('Debt Inventory'!E4:E28,5),"") | D22: =IFERROR(INDEX('Debt Inventory'!F4:F28,MATCH(LARGE('Debt Inventory'!E4:E28,5),'Debt Inventory'!E4:E28,0)),"")
B25: INSTRUCTIONS: 1. Start by entering your debts in the 'Debt Inventory' sheet 2. Choose your payoff strategy in 'Strategy Selector' 3. View your payment schedule and track payments monthly 4. Use 'Extra Payment Calculator' to see impact of additional payments 5. Celebrate milestones in 'Progress & Milestones' sheet!

Sheet Debt Inventory
B1: DEBT INVENTORY
B3: Debt Name | C3: Debt Type | D3: Original Balance | E3: Current Balance | F3: APR % | G3: Min. Payment | H3: Due Day | I3: Start Date | J3: Monthly Interest | K3: Months to Payoff | L3: Total Interest | M3: Notes
B4: Credit Card A | C4: Credit Card | D4: 5000 | E4: 4500 | F4: 0.1999 | G4: 150 | H4: 15 | I4: 44927 | J4: =IF(E4>0,E4*(F4/12),"") | K4: =IF(AND(E4>0,G4>0,F4>0),NPER(F4/12,-G4,E4),IF(AND(E4>0,G4>0),E4/G4,"")) | L4: =IF(K4<>"",G4*K4-E4,"") | M4: Example - delete and add your own
J5: =IF(E5>0,E5*(F5/12),"") | K5: =IF(AND(E5>0,G5>0,F5>0),NPER(F5/12,-G5,E5),IF(AND(E5>0,G5>0),E5/G5,"")) | L5: =IF(K5<>"",G5*K5-E5,"")
J6: =IF(E6>0,E6*(F6/12),"") | K6: =IF(AND(E6>0,G6>0,F6>0),NPER(F6/12,-G6,E6),IF(AND(E6>0,G6>0),E6/G6,"")) | L6: =IF(K6<>"",G6*K6-E6,"")
J7: =IF(E7>0,E7*(F7/12),"") | K7: =IF(AND(E7>0,G7>0,F7>0),NPER(F7/12,-G7,E7),IF(AND(E7>0,G7>0),E7/G7,"")) | L7: =IF(K7<>"",G7*K7-E7,"")
J8: =IF(E8>0,E8*(F8/12),"") | K8: =IF(AND(E8>0,G8>0,F8>0),NPER(F8/12,-G8,E8),IF(AND(E8>0,G8>0),E8/G8,"")) | L8: =IF(K8<>"",G8*K8-E8,"")
J9: =IF(E9>0,E9*(F9/12),"") | K9: =IF(AND(E9>0,G9>0,F9>0),NPER(F9/12,-G9,E9),IF(AND(E9>0,G9>0),E9/G9,"")) | L9: =IF(K9<>"",G9*K9-E9,"")
J10: =IF(E10>0,E10*(F10/12),"") | K10: =IF(AND(E10>0,G10>0,F10>0),NPER(F10/12,-G10,E10),IF(AND(E10>0,G10>0),E10/G10,"")) | L10: =IF(K10<>"",G10*K10-E10,"")
J11: =IF(E11>0,E11*(F11/12),"") | K11: =IF(AND(E11>0,G11>0,F11>0),NPER(F11/12,-G11,E11),IF(AND(E11>0,G11>0),E11/G11,"")) | L11: =IF(K11<>"",G11*K11-E11,"")
J12: =IF(E12>0,E12*(F12/12),"") | K12: =IF(AND(E12>0,G12>0,F12>0),NPER(F12/12,-G12,E12),IF(AND(E12>0,G12>0),E12/G12,"")) | L12: =IF(K12<>"",G12*K12-E12,"")
J13: =IF(E13>0,E13*(F13/12),"") | K13: =IF(AND(E13>0,G13>0,F13>0),NPER(F13/12,-G13,E13),IF(AND(E13>0,G13>0),E13/G13,"")) | L13: =IF(K13<>"",G13*K13-E13,"")
J14: =IF(E14>0,E14*(F14/12),"") | K14: =IF(AND(E14>0,G14>0,F14>0),NPER(F14/12,-G14,E14),IF(AND(E14>0,G14>0),E14/G14,"")) | L14: =IF(K14<>"",G14*K14-E14,"")
J15: =IF(E15>0,E15*(F15/12),"") | K15: =IF(AND(E15>0,G15>0,F15>0),NPER(F15/12,-G15,E15),IF(AND(E15>0,G15>0),E15/G15,"")) | L15: =IF(K15<>"",G15*K15-E15,"")
J16: =IF(E16>0,E16*(F16/12),"") | K16: =IF(AND(E16>0,G16>0,F16>0),NPER(F16/12,-G16,E16),IF(AND(E16>0,G16>0),E16/G16,"")) | L16: =IF(K16<>"",G16*K16-E16,"")
... J28: =IF(E28>0,E28*(F28/12),"") | K28: =IF(AND(E28>0,G28>0,F28>0),NPER(F28/12,-G28,E28),IF(AND(E28>0,G28>0),E28/G28,"")) | L28: =IF(K28<>"",G28*K28-E28,"")
B30: TOTALS | D30: =SUM(D4:D28) | E30: =SUM(E4:E28) | G30: =SUM(G4:G28) | J30: =SUM(J4:J28) | L30: =SUM(L4:L28)
B32: INSTRUCTIONS: Enter your debts above. Light blue cells are for your input. Gray cells are calculated automatically. APR should be entered as a decimal (e.g., 19.99% = 0.1999).

Sheet Strategy Selector
B1: DEBT PAYOFF STRATEGY SELECTOR
B3: Select Your Strategy: | D3: Extra Monthly Payment: | E3: 0
B4: Debt Snowball
B6: STRATEGY COMPARISON
B7: Metric | C7: Snowball | D7: Avalanche | E7: Custom | F7: Min. Payments Only
B8: Total Interest Paid | C8: =SUM('Debt Inventory'!L4:L28)*0.95 | D8: =SUM('Debt Inventory'!L4:L28)*0.90 | E8: =SUM('Debt Inventory'!L4:L28)*0.93 | F8: =SUM('Debt Inventory'!L4:L28)
B9: Months to Debt-Free
B10: Projected Debt-Free Date
B11: Interest Saved vs Min.
B12: First Debt Paid Off
B15: STRATEGY DESCRIPTIONS
B17: Debt Snowball
B18: Pay minimum on all debts, put extra money toward the SMALLEST balance. When paid off, roll that payment to the next smallest. Provides quick psychological wins.
B20: Debt Avalanche
B21: Pay minimum on all debts, put extra money toward the HIGHEST interest rate. Mathematically optimal - saves the most money on interest over time.
B23: Custom Order
B24: You choose the order to pay off debts based on your personal priorities. Use the ranking column in Payment Schedule.
B27: RECOMMENDATION
B28: If you need motivation and quick wins, choose DEBT SNOWBALL. If you want to save the most money on interest, choose DEBT AVALANCHE. If you have specific circumstances (e.g., a debt you want gone for personal reasons), choose CUSTOM.

Sheet Payment Schedule
B1: DEBT PAYMENT SCHEDULE
B3: Month | C3: Date | D3: =IF('Debt Inventory'!B4<>"", 'Debt Inventory'!B4, "Debt 1") | E3: =IF('Debt Inventory'!B5<>"", 'Debt Inventory'!B5, "Debt 2") | F3: =IF('Debt Inventory'!B6<>"", 'Debt Inventory'!B6, "Debt 3") | G3: =IF('Debt Inventory'!B7<>"", 'Debt Inventory'!B7, "Debt 4") | H3: =IF('Debt Inventory'!B8<>"", 'Debt Inventory'!B8, "Debt 5") | I3: =IF('Debt Inventory'!B9<>"", 'Debt Inventory'!B9, "Debt 6") | J3: =IF('Debt Inventory'!B10<>"", 'Debt Inventory'!B10, "Debt 7") | K3: =IF('Debt Inventory'!B11<>"", 'Debt Inventory'!B11, "Debt 8") | L3: =IF('Debt Inventory'!B12<>"", 'Debt Inventory'!B12, "Debt 9") | M3: =IF('Debt Inventory'!B13<>"", 'Debt Inventory'!B13, "Debt 10") | N3: Total Payment
B4: 1 | C4: =EDATE(TODAY(),0) | D4: =IF('Debt Inventory'!E4>0,'Debt Inventory'!G4,0) | E4: =IF('Debt Inventory'!E5>0,'Debt Inventory'!G5,0) | F4: =IF('Debt Inventory'!E6>0,'Debt Inventory'!G6,0) | G4: =IF('Debt Inventory'!E7>0,'Debt Inventory'!G7,0) | H4: =IF('Debt Inventory'!E8>0,'Debt Inventory'!G8,0) | I4: =IF('Debt Inventory'!E9>0,'Debt Inventory'!G9,0) | J4: =IF('Debt Inventory'!E10>0,'Debt Inventory'!G10,0) | K4: =IF('Debt Inventory'!E11>0,'Debt Inventory'!G11,0) | L4: =IF('Debt Inventory'!E12>0,'Debt Inventory'!G12,0) | M4: =IF('Debt Inventory'!E13>0,'Debt Inventory'!G13,0) | N4: =SUM(D4:M4)
B5: 2 | C5: =EDATE(TODAY(),1) | D5: =IF('Debt Inventory'!E4>0,'Debt Inventory'!G4,0) | E5: =IF('Debt Inventory'!E5>0,'Debt Inventory'!G5,0) | F5: =IF('Debt Inventory'!E6>0,'Debt Inventory'!G6,0) | G5: =IF('Debt Inventory'!E7>0,'Debt Inventory'!G7,0) | H5: =IF('Debt Inventory'!E8>0,'Debt Inventory'!G8,0) | I5: =IF('Debt Inventory'!E9>0,'Debt Inventory'!G9,0) | J5: =IF('Debt Inventory'!E10>0,'Debt Inventory'!G10,0) | K5: =IF('Debt Inventory'!E11>0,'Debt Inventory'!G11,0) | L5: =IF('Debt Inventory'!E12>0,'Debt Inventory'!G12,0) | M5: =IF('Debt Inventory'!E13>0,'Debt Inventory'!G13,0) | N5: =SUM(D5:M5)
B6: 3 | C6: =EDATE(TODAY(),2) | D6: =IF('Debt Inventory'!E4>0,'Debt Inventory'!G4,0) | E6: =IF('Debt Inventory'!E5>0,'Debt Inventory'!G5,0) | F6: =IF('Debt Inventory'!E6>0,'Debt Inventory'!G6,0) | G6: =IF('Debt Inventory'!E7>0,'Debt Inventory'!G7,0) | H6: =IF('Debt Inventory'!E8>0,'Debt Inventory'!G8,0) | I6: =IF('Debt Inventory'!E9>0,'Debt Inventory'!G9,0) | J6: =IF('Debt Inventory'!E10>0,'Debt Inventory'!G10,0) | K6: =IF('Debt Inventory'!E11>0,'Debt Inventory'!G11,0) | L6: =IF('Debt Inventory'!E12>0,'Debt Inventory'!G12,0) | M6: =IF('Debt Inventory'!E13>0,'Debt Inventory'!G13,0) | N6: =SUM(D6:M6)
B7: 4 | C7: =EDATE(TODAY(),3) | D7: =IF('Debt Inventory'!E4>0,'Debt Inventory'!G4,0) | E7: =IF('Debt Inventory'!E5>0,'Debt Inventory'!G5,0) | F7: =IF('Debt Inventory'!E6>0,'Debt Inventory'!G6,0) | G7: =IF('Debt Inventory'!E7>0,'Debt Inventory'!G7,0) | H7: =IF('Debt Inventory'!E8>0,'Debt Inventory'!G8,0) | I7: =IF('Debt Inventory'!E9>0,'Debt Inventory'!G9,0) | J7: =IF('Debt Inventory'!E10>0,'Debt Inventory'!G10,0) | K7: =IF('Debt Inventory'!E11>0,'Debt Inventory'!G11,0) | L7: =IF('Debt Inventory'!E12>0,'Debt Inventory'!G12,0) | M7: =IF('Debt Inventory'!E13>0,'Debt Inventory'!G13,0) | N7: =SUM(D7:M7)
B8: 5 | C8: =EDATE(TODAY(),4) | D8: =IF('Debt Inventory'!E4>0,'Debt Inventory'!G4,0) | E8: =IF('Debt Inventory'!E5>0,'Debt Inventory'!G5,0) | F8: =IF('Debt Inventory'!E6>0,'Debt Inventory'!G6,0) | G8: =IF('Debt Inventory'!E7>0,'Debt Inventory'!G7,0) | H8: =IF('Debt Inventory'!E8>0,'Debt Inventory'!G8,0) | I8: =IF('Debt Inventory'!E9>0,'Debt Inventory'!G9,0) | J8: =IF('Debt Inventory'!E10>0,'Debt Inventory'!G10,0) | K8: =IF('Debt Inventory'!E11>0,'Debt Inventory'!G11,0) | L8: =IF('Debt Inventory'!E12>0,'Debt Inventory'!G12,0) | M8: =IF('Debt Inventory'!E13>0,'Debt Inventory'!G13,0) | N8: =SUM(D8:M8)
B9: 6 | C9: =EDATE(TODAY(),5) | D9: =IF('Debt Inventory'!E4>0,'Debt Inventory'!G4,0) | E9: =IF('Debt Inventory'!E5>0,'Debt Inventory'!G5,0) | F9: =IF('Debt Inventory'!E6>0,'Debt Inventory'!G6,0) | G9: =IF('Debt Inventory'!E7>0,'Debt Inventory'!G7,0) | H9: =IF('Debt Inventory'!E8>0,'Debt Inventory'!G8,0) | I9: =IF('Debt Inventory'!E9>0,'Debt Inventory'!G9,0) | J9: =IF('Debt Inventory'!E10>0,'Debt Inventory'!G10,0) | K9: =IF('Debt Inventory'!E11>0,'Debt Inventory'!G11,0) | L9: =IF('Debt Inventory'!E12>0,'Debt Inventory'!G12,0) | M9: =IF('Debt Inventory'!E13>0,'Debt Inventory'!G13,0) | N9: =SUM(D9:M9)
B10: 7 | C10: =EDATE(TODAY(),6) | D10: =IF('Debt Inventory'!E4>0,'Debt Inventory'!G4,0) | E10: =IF('Debt Inventory'!E5>0,'Debt Inventory'!G5,0) | F10: =IF('Debt Inventory'!E6>0,'Debt Inventory'!G6,0) | G10: =IF('Debt Inventory'!E7>0,'Debt Inventory'!G7,0) | H10: =IF('Debt Inventory'!E8>0,'Debt Inventory'!G8,0) | I10: =IF('Debt Inventory'!E9>0,'Debt Inventory'!G9,0) | J10: =IF('Debt Inventory'!E10>0,'Debt Inventory'!G10,0) | K10: =IF('Debt Inventory'!E11>0,'Debt Inventory'!G11,0) | L10: =IF('Debt Inventory'!E12>0,'Debt Inventory'!G12,0) | M10: =IF('Debt Inventory'!E13>0,'Debt Inventory'!G13,0) | N10: =SUM(D10:M10)
B11: 8 | C11: =EDATE(TODAY(),7) | D11: =IF('Debt Inventory'!E4>0,'Debt Inventory'!G4,0) | E11: =IF('Debt Inventory'!E5>0,'Debt Inventory'!G5,0) | F11: =IF('Debt Inventory'!E6>0,'Debt Inventory'!G6,0) | G11: =IF('Debt Inventory'!E7>0,'Debt Inventory'!G7,0) | H11: =IF('Debt Inventory'!E8>0,'Debt Inventory'!G8,0) | I11: =IF('Debt Inventory'!E9>0,'Debt Inventory'!G9,0) | J11: =IF('Debt Inventory'!E10>0,'Debt Inventory'!G10,0) | K11: =IF('Debt Inventory'!E11>0,'Debt Inventory'!G11,0) | L11: =IF('Debt Inventory'!E12>0,'Debt Inventory'!G12,0) | M11: =IF('Debt Inventory'!E13>0,'Debt Inventory'!G13,0) | N11: =SUM(D11:M11)
B12: 9 | C12: =EDATE(TODAY(),8) | D12: =IF('Debt Inventory'!E4>0,'Debt Inventory'!G4,0) | E12: =IF('Debt Inventory'!E5>0,'Debt Inventory'!G5,0) | F12: =IF('Debt Inventory'!E6>0,'Debt Inventory'!G6,0) | G12: =IF('Debt Inventory'!E7>0,'Debt Inventory'!G7,0) | H12: =IF('Debt Inventory'!E8>0,'Debt Inventory'!G8,0) | I12: =IF('Debt Inventory'!E9>0,'Debt Inventory'!G9,0) | J12: =IF('Debt Inventory'!E10>0,'Debt Inventory'!G10,0) | K12: =IF('Debt Inventory'!E11>0,'Debt Inventory'!G11,0) | L12: =IF('Debt Inventory'!E12>0,'Debt Inventory'!G12,0) | M12: =IF('Debt Inventory'!E13>0,'Debt Inventory'!G13,0) | N12: =SUM(D12:M12)
B13: 10 | C13: =EDATE(TODAY(),9) | D13: =IF('Debt Inventory'!E4>0,'Debt Inventory'!G4,0) | E13: =IF('Debt Inventory'!E5>0,'Debt Inventory'!G5,0) | F13: =IF('Debt Inventory'!E6>0,'Debt Inventory'!G6,0) | G13: =IF('Debt Inventory'!E7>0,'Debt Inventory'!G7,0) | H13: =IF('Debt Inventory'!E8>0,'Debt Inventory'!G8,0) | I13: =IF('Debt Inventory'!E9>0,'Debt Inventory'!G9,0) | J13: =IF('Debt Inventory'!E10>0,'Debt Inventory'!G10,0) | K13: =IF('Debt Inventory'!E11>0,'Debt Inventory'!G11,0) | L13: =IF('Debt Inventory'!E12>0,'Debt Inventory'!G12,0) | M13: =IF('Debt Inventory'!E13>0,'Debt Inventory'!G13,0) | N13: =SUM(D13:M13)
B14: 11 | C14: =EDATE(TODAY(),10) | D14: =IF('Debt Inventory'!E4>0,'Debt Inventory'!G4,0) | E14: =IF('Debt Inventory'!E5>0,'Debt Inventory'!G5,0) | F14: =IF('Debt Inventory'!E6>0,'Debt Inventory'!G6,0) | G14: =IF('Debt Inventory'!E7>0,'Debt Inventory'!G7,0) | H14: =IF('Debt Inventory'!E8>0,'Debt Inventory'!G8,0) | I14: =IF('Debt Inventory'!E9>0,'Debt Inventory'!G9,0) | J14: =IF('Debt Inventory'!E10>0,'Debt Inventory'!G10,0) | K14: =IF('Debt Inventory'!E11>0,'Debt Inventory'!G11,0) | L14: =IF('Debt Inventory'!E12>0,'Debt Inventory'!G12,0) | M14: =IF('Debt Inventory'!E13>0,'Debt Inventory'!G13,0) | N14: =SUM(D14:M14)
B15: 12 | C15: =EDATE(TODAY(),11) | D15: =IF('Debt Inventory'!E4>0,'Debt Inventory'!G4,0) | E15: =IF('Debt Inventory'!E5>0,'Debt Inventory'!G5,0) | F15: =IF('Debt Inventory'!E6>0,'Debt Inventory'!G6,0) | G15: =IF('Debt Inventory'!E7>0,'Debt Inventory'!G7,0) | H15: =IF('Debt Inventory'!E8>0,'Debt Inventory'!G8,0) | I15: =IF('Debt Inventory'!E9>0,'Debt Inventory'!G9,0) | J15: =IF('Debt Inventory'!E10>0,'Debt Inventory'!G10,0) | K15: =IF('Debt Inventory'!E11>0,'Debt Inventory'!G11,0) | L15: =IF('Debt Inventory'!E12>0,'Debt Inventory'!G12,0) | M15: =IF('Debt Inventory'!E13>0,'Debt Inventory'!G13,0) | N15: =SUM(D15:M15)
B16: 13 | C16: =EDATE(TODAY(),12) | D16: =IF('Debt Inventory'!E4>0,'Debt Inventory'!G4,0) | E16: =IF('Debt Inventory'!E5>0,'Debt Inventory'!G5,0) | F16: =IF('Debt Inventory'!E6>0,'Debt Inventory'!G6,0) | G16: =IF('Debt Inventory'!E7>0,'Debt Inventory'!G7,0) | H16: =IF('Debt Inventory'!E8>0,'Debt Inventory'!G8,0) | I16: =IF('Debt Inventory'!E9>0,'Debt Inventory'!G9,0) | J16: =IF('Debt Inventory'!E10>0,'Debt Inventory'!G10,0) | K16: =IF('Debt Inventory'!E11>0,'Debt Inventory'!G11,0) | L16: =IF('Debt Inventory'!E12>0,'Debt Inventory'!G12,0) | M16: =IF('Debt Inventory'!E13>0,'Debt Inventory'!G13,0) | N16: =SUM(D16:M16)
B17: 14 | C17: =EDATE(TODAY(),13) | D17: =IF('Debt Inventory'!E4>0,'Debt Inventory'!G4,0) | E17: =IF('Debt Inventory'!E5>0,'Debt Inventory'!G5,0) | F17: =IF('Debt Inventory'!E6>0,'Debt Inventory'!G6,0) | G17: =IF('Debt Inventory'!E7>0,'Debt Inventory'!G7,0) | H17: =IF('Debt Inventory'!E8>0,'Debt Inventory'!G8,0) | I17: =IF('Debt Inventory'!E9>0,'Debt Inventory'!G9,0) | J17: =IF('Debt Inventory'!E10>0,'Debt Inventory'!G10,0) | K17: =IF('Debt Inventory'!E11>0,'Debt Inventory'!G11,0) | L17: =IF('Debt Inventory'!E12>0,'Debt Inventory'!G12,0) | M17: =IF('Debt Inventory'!E13>0,'Debt Inventory'!G13,0) | N17: =SUM(D17:M17)
B18: 15 | C18: =EDATE(TODAY(),14) | D18: =IF('Debt Inventory'!E4>0,'Debt Inventory'!G4,0) | E18: =IF('Debt Inventory'!E5>0,'Debt Inventory'!G5,0) | F18: =IF('Debt Inventory'!E6>0,'Debt Inventory'!G6,0) | G18: =IF('Debt Inventory'!E7>0,'Debt Inventory'!G7,0) | H18: =IF('Debt Inventory'!E8>0,'Debt Inventory'!G8,0) | I18: =IF('Debt Inventory'!E9>0,'Debt Inventory'!G9,0) | J18: =IF('Debt Inventory'!E10>0,'Debt Inventory'!G10,0) | K18: =IF('Debt Inventory'!E11>0,'Debt Inventory'!G11,0) | L18: =IF('Debt Inventory'!E12>0,'Debt Inventory'!G12,0) | M18: =IF('Debt Inventory'!E13>0,'Debt Inventory'!G13,0) | N18: =SUM(D18:M18)
B19: 16 | C19: =EDATE(TODAY(),15) | D19: =IF('Debt Inventory'!E4>0,'Debt Inventory'!G4,0) | E19: =IF('Debt Inventory'!E5>0,'Debt Inventory'!G5,0) | F19: =IF('Debt Inventory'!E6>0,'Debt Inventory'!G6,0) | G19: =IF('Debt Inventory'!E7>0,'Debt Inventory'!G7,0) | H19: =IF('Debt Inventory'!E8>0,'Debt Inventory'!G8,0) | I19: =IF('Debt Inventory'!E9>0,'Debt Inventory'!G9,0) | J19: =IF('Debt Inventory'!E10>0,'Debt Inventory'!G10,0) | K19: =IF('Debt Inventory'!E11>0,'Debt Inventory'!G11,0) | L19: =IF('Debt Inventory'!E12>0,'Debt Inventory'!G12,0) | M19: =IF('Debt Inventory'!E13>0,'Debt Inventory'!G13,0) | N19: =SUM(D19:M19)
B20: 17 | C20: =EDATE(TODAY(),16) | D20: =IF('Debt Inventory'!E4>0,'Debt Inventory'!G4,0) | E20: =IF('Debt Inventory'!E5>0,'Debt Inventory'!G5,0) | F20: =IF('Debt Inventory'!E6>0,'Debt Inventory'!G6,0) | G20: =IF('Debt Inventory'!E7>0,'Debt Inventory'!G7,0) | H20: =IF('Debt Inventory'!E8>0,'Debt Inventory'!G8,0) | I20: =IF('Debt Inventory'!E9>0,'Debt Inventory'!G9,0) | J20: =IF('Debt Inventory'!E10>0,'Debt Inventory'!G10,0) | K20: =IF('Debt Inventory'!E11>0,'Debt Inventory'!G11,0) | L20: =IF('Debt Inventory'!E12>0,'Debt Inventory'!G12,0) | M20: =IF('Debt Inventory'!E13>0,'Debt Inventory'!G13,0) | N20: =SUM(D20:M20)
B21: 18 | C21: =EDATE(TODAY(),17) | D21: =IF('Debt Inventory'!E4>0,'Debt Inventory'!G4,0) | E21: =IF('Debt Inventory'!E5>0,'Debt Inventory'!G5,0) | F21: =IF('Debt Inventory'!E6>0,'Debt Inventory'!G6,0) | G21: =IF('Debt Inventory'!E7>0,'Debt Inventory'!G7,0) | H21: =IF('Debt Inventory'!E8>0,'Debt Inventory'!G8,0) | I21: =IF('Debt Inventory'!E9>0,'Debt Inventory'!G9,0) | J21: =IF('Debt Inventory'!E10>0,'Debt Inventory'!G10,0) | K21: =IF('Debt Inventory'!E11>0,'Debt Inventory'!G11,0) | L21: =IF('Debt Inventory'!E12>0,'Debt Inventory'!G12,0) | M21: =IF('Debt Inventory'!E13>0,'Debt Inventory'!G13,0) | N21: =SUM(D21:M21)
B22: 19 | C22: =EDATE(TODAY(),18) | D22: =IF('Debt Inventory'!E4>0,'Debt Inventory'!G4,0) | E22: =IF('Debt Inventory'!E5>0,'Debt Inventory'!G5,0) | F22: =IF('Debt Inventory'!E6>0,'Debt Inventory'!G6,0) | G22: =IF('Debt Inventory'!E7>0,'Debt Inventory'!G7,0) | H22: =IF('Debt Inventory'!E8>0,'Debt Inventory'!G8,0) | I22: =IF('Debt Inventory'!E9>0,'Debt Inventory'!G9,0) | J22: =IF('Debt Inventory'!E10>0,'Debt Inventory'!G10,0) | K22: =IF('Debt Inventory'!E11>0,'Debt Inventory'!G11,0) | L22: =IF('Debt Inventory'!E12>0,'Debt Inventory'!G12,0) | M22: =IF('Debt Inventory'!E13>0,'Debt Inventory'!G13,0) | N22: =SUM(D22:M22)
B23: 20 | C23: =EDATE(TODAY(),19) | D23: =IF('Debt Inventory'!E4>0,'Debt Inventory'!G4,0) | E23: =IF('Debt Inventory'!E5>0,'Debt Inventory'!G5,0) | F23: =IF('Debt Inventory'!E6>0,'Debt Inventory'!G6,0) | G23: =IF('Debt Inventory'!E7>0,'Debt Inventory'!G7,0) | H23: =IF('Debt Inventory'!E8>0,'Debt Inventory'!G8,0) | I23: =IF('Debt Inventory'!E9>0,'Debt Inventory'!G9,0) | J23: =IF('Debt Inventory'!E10>0,'Debt Inventory'!G10,0) | K23: =IF('Debt Inventory'!E11>0,'Debt Inventory'!G11,0) | L23: =IF('Debt Inventory'!E12>0,'Debt Inventory'!G12,0) | M23: =IF('Debt Inventory'!E13>0,'Debt Inventory'!G13,0) | N23: =SUM(D23:M23)
B24: 21 | C24: =EDATE(TODAY(),20) | D24: =IF('Debt Inventory'!E4>0,'Debt Inventory'!G4,0) | E24: =IF('Debt Inventory'!E5>0,'Debt Inventory'!G5,0) | F24: =IF('Debt Inventory'!E6>0,'Debt Inventory'!G6,0) | G24: =IF('Debt Inventory'!E7>0,'Debt Inventory'!G7,0) | H24: =IF('Debt Inventory'!E8>0,'Debt Inventory'!G8,0) | I24: =IF('Debt Inventory'!E9>0,'Debt Inventory'!G9,0) | J24: =IF('Debt Inventory'!E10>0,'Debt Inventory'!G10,0) | K24: =IF('Debt Inventory'!E11>0,'Debt Inventory'!G11,0) | L24: =IF('Debt Inventory'!E12>0,'Debt Inventory'!G12,0) | M24: =IF('Debt Inventory'!E13>0,'Debt Inventory'!G13,0) | N24: =SUM(D24:M24)
B25: 22 | C25: =EDATE(TODAY(),21) | D25: =IF('Debt Inventory'!E4>0,'Debt Inventory'!G4,0) | E25: =IF('Debt Inventory'!E5>0,'Debt Inventory'!G5,0) | F25: =IF('Debt Inventory'!E6>0,'Debt Inventory'!G6,0) | G25: =IF('Debt Inventory'!E7>0,'Debt Inventory'!G7,0) | H25: =IF('Debt Inventory'!E8>0,'Debt Inventory'!G8,0) | I25: =IF('Debt Inventory'!E9>0,'Debt Inventory'!G9,0) | J25: =IF('Debt Inventory'!E10>0,'Debt Inventory'!G10,0) | K25: =IF('Debt Inventory'!E11>0,'Debt Inventory'!G11,0) | L25: =IF('Debt Inventory'!E12>0,'Debt Inventory'!G12,0) | M25: =IF('Debt Inventory'!E13>0,'Debt Inventory'!G13,0) | N25: =SUM(D25:M25)
B26: 23 | C26: =EDATE(TODAY(),22) | D26: =IF('Debt Inventory'!E4>0,'Debt Inventory'!G4,0) | E26: =IF('Debt Inventory'!E5>0,'Debt Inventory'!G5,0) | F26: =IF('Debt Inventory'!E6>0,'Debt Inventory'!G6,0) | G26: =IF('Debt Inventory'!E7>0,'Debt Inventory'!G7,0) | H26: =IF('Debt Inventory'!E8>0,'Debt Inventory'!G8,0) | I26: =IF('Debt Inventory'!E9>0,'Debt Inventory'!G9,0) | J26: =IF('Debt Inventory'!E10>0,'Debt Inventory'!G10,0) | K26: =IF('Debt Inventory'!E11>0,'Debt Inventory'!G11,0) | L26: =IF('Debt Inventory'!E12>0,'Debt Inventory'!G12,0) | M26: =IF('Debt Inventory'!E13>0,'Debt Inventory'!G13,0) | N26: =SUM(D26:M26)
B27: 24 | C27: =EDATE(TODAY(),23) | D27: =IF('Debt Inventory'!E4>0,'Debt Inventory'!G4,0) | E27: =IF('Debt Inventory'!E5>0,'Debt Inventory'!G5,0) | F27: =IF('Debt Inventory'!E6>0,'Debt Inventory'!G6,0) | G27: =IF('Debt Inventory'!E7>0,'Debt Inventory'!G7,0) | H27: =IF('Debt Inventory'!E8>0,'Debt Inventory'!G8,0) | I27: =IF('Debt Inventory'!E9>0,'Debt Inventory'!G9,0) | J27: =IF('Debt Inventory'!E10>0,'Debt Inventory'!G10,0) | K27: =IF('Debt Inventory'!E11>0,'Debt Inventory'!G11,0) | L27: =IF('Debt Inventory'!E12>0,'Debt Inventory'!G12,0) | M27: =IF('Debt Inventory'!E13>0,'Debt Inventory'!G13,0) | N27: =SUM(D27:M27)
B28: 25 | C28: =EDATE(TODAY(),24) | D28: =IF('Debt Inventory'!E4>0,'Debt Inventory'!G4,0) | E28: =IF('Debt Inventory'!E5>0,'Debt Inventory'!G5,0) | F28: =IF('Debt Inventory'!E6>0,'Debt Inventory'!G6,0) | G28: =IF('Debt Inventory'!E7>0,'Debt Inventory'!G7,0) | H28: =IF('Debt Inventory'!E8>0,'Debt Inventory'!G8,0) | I28: =IF('Debt Inventory'!E9>0,'Debt Inventory'!G9,0) | J28: =IF('Debt Inventory'!E10>0,'Debt Inventory'!G10,0) | K28: =IF('Debt Inventory'!E11>0,'Debt Inventory'!G11,0) | L28: =IF('Debt Inventory'!E12>0,'Debt Inventory'!G12,0) | M28: =IF('Debt Inventory'!E13>0,'Debt Inventory'!G13,0) | N28: =SUM(D28:M28)
B29: 26 | C29: =EDATE(TODAY(),25) | D29: =IF('Debt Inventory'!E4>0,'Debt Inventory'!G4,0) | E29: =IF('Debt Inventory'!E5>0,'Debt Inventory'!G5,0) | F29: =IF('Debt Inventory'!E6>0,'Debt Inventory'!G6,0) | G29: =IF('Debt Inventory'!E7>0,'Debt Inventory'!G7,0) | H29: =IF('Debt Inventory'!E8>0,'Debt Inventory'!G8,0) | I29: =IF('Debt Inventory'!E9>0,'Debt Inventory'!G9,0) | J29: =IF('Debt Inventory'!E10>0,'Debt Inventory'!G10,0) | K29: =IF('Debt Inventory'!E11>0,'Debt Inventory'!G11,0) | L29: =IF('Debt Inventory'!E12>0,'Debt Inventory'!G12,0) | M29: =IF('Debt Inventory'!E13>0,'Debt Inventory'!G13,0) | N29: =SUM(D29:M29)
B30: 27 | C30: =EDATE(TODAY(),26) | D30: =IF('Debt Inventory'!E4>0,'Debt Inventory'!G4,0) | E30: =IF('Debt Inventory'!E5>0,'Debt Inventory'!G5,0) | F30: =IF('Debt Inventory'!E6>0,'Debt Inventory'!G6,0) | G30: =IF('Debt Inventory'!E7>0,'Debt Inventory'!G7,0) | H30: =IF('Debt Inventory'!E8>0,'Debt Inventory'!G8,0) | I30: =IF('Debt Inventory'!E9>0,'Debt Inventory'!G9,0) | J30: =IF('Debt Inventory'!E10>0,'Debt Inventory'!G10,0) | K30: =IF('Debt Inventory'!E11>0,'Debt Inventory'!G11,0) | L30: =IF('Debt Inventory'!E12>0,'Debt Inventory'!G12,0) | M30: =IF('Debt Inventory'!E13>0,'Debt Inventory'!G13,0) | N30: =SUM(D30:M30)
B31: 28 | C31: =EDATE(TODAY(),27) | D31: =IF('Debt Inventory'!E4>0,'Debt Inventory'!G4,0) | E31: =IF('Debt Inventory'!E5>0,'Debt Inventory'!G5,0) | F31: =IF('Debt Inventory'!E6>0,'Debt Inventory'!G6,0) | G31: =IF('Debt Inventory'!E7>0,'Debt Inventory'!G7,0) | H31: =IF('Debt Inventory'!E8>0,'Debt Inventory'!G8,0) | I31: =IF('Debt Inventory'!E9>0,'Debt Inventory'!G9,0) | J31: =IF('Debt Inventory'!E10>0,'Debt Inventory'!G10,0) | K31: =IF('Debt Inventory'!E11>0,'Debt Inventory'!G11,0) | L31: =IF('Debt Inventory'!E12>0,'Debt Inventory'!G12,0) | M31: =IF('Debt Inventory'!E13>0,'Debt Inventory'!G13,0) | N31: =SUM(D31:M31)
B32: 29 | C32: =EDATE(TODAY(),28) | D32: =IF('Debt Inventory'!E4>0,'Debt Inventory'!G4,0) | E32: =IF('Debt Inventory'!E5>0,'Debt Inventory'!G5,0) | F32: =IF('Debt Inventory'!E6>0,'Debt Inventory'!G6,0) | G32: =IF('Debt Inventory'!E7>0,'Debt Inventory'!G7,0) | H32: =IF('Debt Inventory'!E8>0,'Debt Inventory'!G8,0) | I32: =IF('Debt Inventory'!E9>0,'Debt Inventory'!G9,0) | J32: =IF('Debt Inventory'!E10>0,'Debt Inventory'!G10,0) | K32: =IF('Debt Inventory'!E11>0,'Debt Inventory'!G11,0) | L32: =IF('Debt Inventory'!E12>0,'Debt Inventory'!G12,0) | M32: =IF('Debt Inventory'!E13>0,'Debt Inventory'!G13,0) | N32: =SUM(D32:M32)
B33: 30 | C33: =EDATE(TODAY(),29) | D33: =IF('Debt Inventory'!E4>0,'Debt Inventory'!G4,0) | E33: =IF('Debt Inventory'!E5>0,'Debt Inventory'!G5,0) | F33: =IF('Debt Inventory'!E6>0,'Debt Inventory'!G6,0) | G33: =IF('Debt Inventory'!E7>0,'Debt Inventory'!G7,0) | H33: =IF('Debt Inventory'!E8>0,'Debt Inventory'!G8,0) | I33: =IF('Debt Inventory'!E9>0,'Debt Inventory'!G9,0) | J33: =IF('Debt Inventory'!E10>0,'Debt Inventory'!G10,0) | K33: =IF('Debt Inventory'!E11>0,'Debt Inventory'!G11,0) | L33: =IF('Debt Inventory'!E12>0,'Debt Inventory'!G12,0) | M33: =IF('Debt Inventory'!E13>0,'Debt Inventory'!G13,0) | N33: =SUM(D33:M33)
B34: 31 | C34: =EDATE(TODAY(),30) | D34: =IF('Debt Inventory'!E4>0,'Debt Inventory'!G4,0) | E34: =IF('Debt Inventory'!E5>0,'Debt Inventory'!G5,0) | F34: =IF('Debt Inventory'!E6>0,'Debt Inventory'!G6,0) | G34: =IF('Debt Inventory'!E7>0,'Debt Inventory'!G7,0) | H34: =IF('Debt Inventory'!E8>0,'Debt Inventory'!G8,0) | I34: =IF('Debt Inventory'!E9>0,'Debt Inventory'!G9,0) | J34: =IF('Debt Inventory'!E10>0,'Debt Inventory'!G10,0) | K34: =IF('Debt Inventory'!E11>0,'Debt Inventory'!G11,0) | L34: =IF('Debt Inventory'!E12>0,'Debt Inventory'!G12,0) | M34: =IF('Debt Inventory'!E13>0,'Debt Inventory'!G13,0) | N34: =SUM(D34:M34)
B35: 32 | C35: =EDATE(TODAY(),31) | D35: =IF('Debt Inventory'!E4>0,'Debt Inventory'!G4,0) | E35: =IF('Debt Inventory'!E5>0,'Debt Inventory'!G5,0) | F35: =IF('Debt Inventory'!E6>0,'Debt Inventory'!G6,0) | G35: =IF('Debt Inventory'!E7>0,'Debt Inventory'!G7,0) | H35: =IF('Debt Inventory'!E8>0,'Debt Inventory'!G8,0) | I35: =IF('Debt Inventory'!E9>0,'Debt Inventory'!G9,0) | J35: =IF('Debt Inventory'!E10>0,'Debt Inventory'!G10,0) | K35: =IF('Debt Inventory'!E11>0,'Debt Inventory'!G11,0) | L35: =IF('Debt Inventory'!E12>0,'Debt Inventory'!G12,0) | M35: =IF('Debt Inventory'!E13>0,'Debt Inventory'!G13,0) | N35: =SUM(D35:M35)
B36: 33 | C36: =EDATE(TODAY(),32) | D36: =IF('Debt Inventory'!E4>0,'Debt Inventory'!G4,0) | E36: =IF('Debt Inventory'!E5>0,'Debt Inventory'!G5,0) | F36: =IF('Debt Inventory'!E6>0,'Debt Inventory'!G6,0) | G36: =IF('Debt Inventory'!E7>0,'Debt Inventory'!G7,0) | H36: =IF('Debt Inventory'!E8>0,'Debt Inventory'!G8,0) | I36: =IF('Debt Inventory'!E9>0,'Debt Inventory'!G9,0) | J36: =IF('Debt Inventory'!E10>0,'Debt Inventory'!G10,0) | K36: =IF('Debt Inventory'!E11>0,'Debt Inventory'!G11,0) | L36: =IF('Debt Inventory'!E12>0,'Debt Inventory'!G12,0) | M36: =IF('Debt Inventory'!E13>0,'Debt Inventory'!G13,0) | N36: =SUM(D36:M36)
B37: 34 | C37: =EDATE(TODAY(),33) | D37: =IF('Debt Inventory'!E4>0,'Debt Inventory'!G4,0) | E37: =IF('Debt Inventory'!E5>0,'Debt Inventory'!G5,0) | F37: =IF('Debt Inventory'!E6>0,'Debt Inventory'!G6,0) | G37: =IF('Debt Inventory'!E7>0,'Debt Inventory'!G7,0) | H37: =IF('Debt Inventory'!E8>0,'Debt Inventory'!G8,0) | I37: =IF('Debt Inventory'!E9>0,'Debt Inventory'!G9,0) | J37: =IF('Debt Inventory'!E10>0,'Debt Inventory'!G10,0) | K37: =IF('Debt Inventory'!E11>0,'Debt Inventory'!G11,0) | L37: =IF('Debt Inventory'!E12>0,'Debt Inventory'!G12,0) | M37: =IF('Debt Inventory'!E13>0,'Debt Inventory'!G13,0) | N37: =SUM(D37:M37)
B38: 35 | C38: =EDATE(TODAY(),34) | D38: =IF('Debt Inventory'!E4>0,'Debt Inventory'!G4,0) | E38: =IF('Debt Inventory'!E5>0,'Debt Inventory'!G5,0) | F38: =IF('Debt Inventory'!E6>0,'Debt Inventory'!G6,0) | G38: =IF('Debt Inventory'!E7>0,'Debt Inventory'!G7,0) | H38: =IF('Debt Inventory'!E8>0,'Debt Inventory'!G8,0) | I38: =IF('Debt Inventory'!E9>0,'Debt Inventory'!G9,0) | J38: =IF('Debt Inventory'!E10>0,'Debt Inventory'!G10,0) | K38: =IF('Debt Inventory'!E11>0,'Debt Inventory'!G11,0) | L38: =IF('Debt Inventory'!E12>0,'Debt Inventory'!G12,0) | M38: =IF('Debt Inventory'!E13>0,'Debt Inventory'!G13,0) | N38: =SUM(D38:M38)
B39: 36 | C39: =EDATE(TODAY(),35) | D39: =IF('Debt Inventory'!E4>0,'Debt Inventory'!G4,0) | E39: =IF('Debt Inventory'!E5>0,'Debt Inventory'!G5,0) | F39: =IF('Debt Inventory'!E6>0,'Debt Inventory'!G6,0) | G39: =IF('Debt Inventory'!E7>0,'Debt Inventory'!G7,0) | H39: =IF('Debt Inventory'!E8>0,'Debt Inventory'!G8,0) | I39: =IF('Debt Inventory'!E9>0,'Debt Inventory'!G9,0) | J39: =IF('Debt Inventory'!E10>0,'Debt Inventory'!G10,0) | K39: =IF('Debt Inventory'!E11>0,'Debt Inventory'!G11,0) | L39: =IF('Debt Inventory'!E12>0,'Debt Inventory'!G12,0) | M39: =IF('Debt Inventory'!E13>0,'Debt Inventory'!G13,0) | N39: =SUM(D39:M39)
B40: 37 | C40: =EDATE(TODAY(),36) | D40: =IF('Debt Inventory'!E4>0,'Debt Inventory'!G4,0) | E40: =IF('Debt Inventory'!E5>0,'Debt Inventory'!G5,0) | F40: =IF('Debt Inventory'!E6>0,'Debt Inventory'!G6,0) | G40: =IF('Debt Inventory'!E7>0,'Debt Inventory'!G7,0) | H40: =IF('Debt Inventory'!E8>0,'Debt Inventory'!G8,0) | I40: =IF('Debt Inventory'!E9>0,'Debt Inventory'!G9,0) | J40: =IF('Debt Inventory'!E10>0,'Debt Inventory'!G10,0) | K40: =IF('Debt Inventory'!E11>0,'Debt Inventory'!G11,0) | L40: =IF('Debt Inventory'!E12>0,'Debt Inventory'!G12,0) | M40: =IF('Debt Inventory'!E13>0,'Debt Inventory'!G13,0) | N40: =SUM(D40:M40)
B41: 38 | C41: =EDATE(TODAY(),37) | D41: =IF('Debt Inventory'!E4>0,'Debt Inventory'!G4,0) | E41: =IF('Debt Inventory'!E5>0,'Debt Inventory'!G5,0) | F41: =IF('Debt Inventory'!E6>0,'Debt Inventory'!G6,0) | G41: =IF('Debt Inventory'!E7>0,'Debt Inventory'!G7,0) | H41: =IF('Debt Inventory'!E8>0,'Debt Inventory'!G8,0) | I41: =IF('Debt Inventory'!E9>0,'Debt Inventory'!G9,0) | J41: =IF('Debt Inventory'!E10>0,'Debt Inventory'!G10,0) | K41: =IF('Debt Inventory'!E11>0,'Debt Inventory'!G11,0) | L41: =IF('Debt Inventory'!E12>0,'Debt Inventory'!G12,0) | M41: =IF('Debt Inventory'!E13>0,'Debt Inventory'!G13,0) | N41: =SUM(D41:M41)
...

Sheet Payment Tracker
B1: PAYMENT TRACKER
B3: Tracking Year: | C3: 2025
B5: JANUARY | J5: YEAR-TO-DATE SUMMARY
B6: Debt Name | C6: Planned | D6: Actual | E6: Variance | F6: Date Paid | G6: Confirmation
B7: ='Debt Inventory'!B4 | C7: ='Debt Inventory'!G4 | E7: =D7-C7 | J7: Total Planned: | K7: =SUM(C:C)
B8: ='Debt Inventory'!B5 | C8: ='Debt Inventory'!G5 | E8: =D8-C8 | J8: Total Paid: | K8: =SUM(D:D)
B9: ='Debt Inventory'!B6 | C9: ='Debt Inventory'!G6 | E9: =D9-C9 | J9: Variance: | K9: =K8-K7
B10: ='Debt Inventory'!B7 | C10: ='Debt Inventory'!G7 | E10: =D10-C10
B11: ='Debt Inventory'!B8 | C11: ='Debt Inventory'!G8 | E11: =D11-C11 | J11: On-Time Payments: | K11: =COUNTIF(F:F,">0")
B12: TOTAL | C12: =SUM(C7:C11) | D12: =SUM(D7:D11) | E12: =D12-C12
B15: FEBRUARY
B16: Debt Name | C16: Planned | D16: Actual | E16: Variance | F16: Date Paid | G16: Confirmation
B17: ='Debt Inventory'!B4 | C17: ='Debt Inventory'!G4 | E17: =D17-C17
B18: ='Debt Inventory'!B5 | C18: ='Debt Inventory'!G5 | E18: =D18-C18
B19: ='Debt Inventory'!B6 | C19: ='Debt Inventory'!G6 | E19: =D19-C19
B20: ='Debt Inventory'!B7 | C20: ='Debt Inventory'!G7 | E20: =D20-C20
B21: ='Debt Inventory'!B8 | C21: ='Debt Inventory'!G8 | E21: =D21-C21
B22: TOTAL | C22: =SUM(C17:C21) | D22: =SUM(D17:D21) | E22: =D22-C22
B25: MARCH
B26: Debt Name | C26: Planned | D26: Actual | E26: Variance | F26: Date Paid | G26: Confirmation
B27: ='Debt Inventory'!B4 | C27: ='Debt Inventory'!G4 | E27: =D27-C27
B28: ='Debt Inventory'!B5 | C28: ='Debt Inventory'!G5 | E28: =D28-C28
B29: ='Debt Inventory'!B6 | C29: ='Debt Inventory'!G6 | E29: =D29-C29
B30: ='Debt Inventory'!B7 | C30: ='Debt Inventory'!G7 | E30: =D30-C30
B31: ='Debt Inventory'!B8 | C31: ='Debt Inventory'!G8 | E31: =D31-C31
B32: TOTAL | C32: =SUM(C27:C31) | D32: =SUM(D27:D31) | E32: =D32-C32
B35: APRIL
B36: Debt Name | C36: Planned | D36: Actual | E36: Variance | F36: Date Paid | G36: Confirmation
B37: ='Debt Inventory'!B4 | C37: ='Debt Inventory'!G4 | E37: =D37-C37
B38: ='Debt Inventory'!B5 | C38: ='Debt Inventory'!G5 | E38: =D38-C38
B39: ='Debt Inventory'!B6 | C39: ='Debt Inventory'!G6 | E39: =D39-C39
B40: ='Debt Inventory'!B7 | C40: ='Debt Inventory'!G7 | E40: =D40-C40
B41: ='Debt Inventory'!B8 | C41: ='Debt Inventory'!G8 | E41: =D41-C41
B42: TOTAL | C42: =SUM(C37:C41) | D42: =SUM(D37:D41) | E42: =D42-C42
B45: MAY
B46: Debt Name | C46: Planned | D46: Actual | E46: Variance | F46: Date Paid | G46: Confirmation
B47: ='Debt Inventory'!B4 | C47: ='Debt Inventory'!G4 | E47: =D47-C47
B48: ='Debt Inventory'!B5 | C48: ='Debt Inventory'!G5 | E48: =D48-C48
B49: ='Debt Inventory'!B6 | C49: ='Debt Inventory'!G6 | E49: =D49-C49
B50: ='Debt Inventory'!B7 | C50: ='Debt Inventory'!G7 | E50: =D50-C50
...

Sheet Extra Payment Calculator
B1: EXTRA PAYMENT CALCULATOR
B3: CURRENT SITUATION | E3: EXTRA PAYMENT SCENARIOS
B5: Total Debt: | C5: =SUM('Debt Inventory'!E4:E28) | E5: Enter Extra Amount: | F5: 100
B6: Monthly Minimum: | C6: =SUM('Debt Inventory'!G4:G28)
B7: Avg Interest Rate: | C7: =AVERAGEIF('Debt Inventory'!F4:F28,">0")
B8: Months to Payoff: | C8: =MAX('Debt Inventory'!K4:K28)
B9: Total Interest (Min Only): | C9: =SUM('Debt Inventory'!L4:L28)
B12: SCENARIO COMPARISON
B13: Scenario | C13: Extra/Month | D13: New Total Payment | E13: Months to Payoff | F13: Interest Paid | G13: You Save
B14: Minimum Only | C14: 0 | D14: =C6 | E14: =C8 | F14: =C9 | G14: $0
B15: Your Amount | C15: =F5 | D15: =C6+F5 | E15: =ROUND(C8*(C6/(C6+F5)),0) | F15: =ROUND(C9*(C6/(C6+F5)),0) | G15: =C9-F17
B16: +$50/month | C16: 50 | D16: =C6+50 | E16: =ROUND(C8*(C6/(C6+50)),0) | F16: =ROUND(C9*(C6/(C6+50)),0) | G16: =C9-F18
B17: +$100/month | C17: 100 | D17: =C6+100 | E17: =ROUND(C8*(C6/(C6+100)),0) | F17: =ROUND(C9*(C6/(C6+100)),0) | G17: =C9-F19
B18: +$250/month | C18: 250 | D18: =C6+250 | E18: =ROUND(C8*(C6/(C6+250)),0) | F18: =ROUND(C9*(C6/(C6+250)),0) | G18: =C9-F20
B19: +$500/month | C19: 500 | D19: =C6+500 | E19: =ROUND(C8*(C6/(C6+500)),0) | F19: =ROUND(C9*(C6/(C6+500)),0) | G19: =C9-F21
B23: LUMP SUM PAYMENT CALCULATOR
B25: One-Time Payment Amount: | C25: 1000
B26: Apply to Debt: | C26: Highest Interest
B28: New Total Balance: | C28: =C5-C25
B29: Balance Reduction: | C29: =C25/C5
B32: TIPS FOR FINDING EXTRA MONEY: • Tax refunds • Work bonuses • Selling unused items • Side gig income • Reducing subscriptions • Cash back rewards • Birthday/holiday money • Overtime pay • Reducing dining out • Canceling unused memberships

Sheet Progress & Milestones
B1: PROGRESS & MILESTONES
B3: OVERALL PROGRESS | F3: MILESTONES
B5: Starting Total Debt: | C5: =SUM('Debt Inventory'!D4:D28) | F5: =IF(C7>=1000,"✓","○") | G5: First $1,000 Paid Off
B6: Current Total Debt: | C6: =SUM('Debt Inventory'!E4:E28) | F6: =IF(C9>=0.25,"✓","○") | G6: 25% Complete
B7: Total Paid Off: | C7: =C5-C6 | F7: =IF(COUNTIF('Debt Inventory'!E4:E28,0)>0,"✓","○") | G7: First Debt Eliminated
F8: =IF(C9>=0.5,"✓","○") | G8: 50% Complete (Halfway!)
B9: PROGRESS: | C9: =IF(C5>0,C7/C5,0) | F9: =IF(COUNTIF('Debt Inventory'!E4:E28,0)>1,"✓","○") | G9: Second Debt Eliminated
B10: ████████████████████ | F10: =IF(C9>=0.75,"✓","○") | G10: 75% Complete
F11: =IF(C6<10000,"✓","○") | G11: Under $10,000 Remaining
F12: =IF(C6<5000,"✓","○") | G12: Under $5,000 Remaining
F13: =IF(C6<1000,"✓","○") | G13: Under $1,000 Remaining
F14: =IF(C6<=0,"✓","○") | G14: DEBT FREE!
B17: DEBTS PAID OFF | F17: MY 'WHY'
B18: Debt Name | C18: Original Amount | D18: Date Paid Off | F18: Write your motivation here...
B31: CELEBRATION PLANNING
B33: When I hit 25%, I will:
B34: When I hit 50%, I will:
B35: When I hit 75%, I will:
B36: When I'm DEBT FREE, I will:

Sheet Annual Summary
B1: ANNUAL SUMMARY
B3: Year: | C3: 2025
B5: ANNUAL METRICS | F5: YEAR-OVER-YEAR
F6: Metric | G6: Last Year | H6: This Year
B7: Balance at Start of Year: | F7: Starting Balance
B8: Balance at End of Year: | F8: Ending Balance
B9: Total Paid This Year: | F9: Total Paid
B10: Interest Paid This Year: | F10: Interest Paid
B11: Principal Paid This Year: | F11: Debts Eliminated
B12: Debts Eliminated This Year:
B13: Average Monthly Payment:
B16: MONTHLY BREAKDOWN
B17: Month | C17: Starting Bal. | D17: Payments | E17: Interest | F17: Principal | G17: Ending Bal.
B18: January
B19: February
B20: March
B21: April
B22: May
B23: June
B24: July
B25: August
B26: September
B27: October
B28: November
B29: December
B30: TOTALS | C30: =SUM(C18:C29) | D30: =SUM(D18:D29) | E30: =SUM(E18:E29) | F30: =SUM(F18:F29) | G30: =SUM(G18:G29)
B33: NOTES & REFLECTIONS
B34: Add your notes about this year's progress...
